<?xml version="1.0"?>
<robot name="box">

  <material name="grey">
    <color rgba="0.5 0.5 0.5 1"/>
  </material>
  <material name="blue">
    <color rgba="0.0 0.0 1.0 1"/>
  </material>
  <material name="red">
    <color rgba="1.0 0.0 0.0 1"/>
  </material>

  <link name="base_link">
    <!-- Visual appearance (mesh) -->
    <visual>
      <origin xyz="0 0 0.223" rpy="0 0 0"/>
      <geometry>
        <box size = "0.49 0.35 0.02"/>
      </geometry>
      <material name="blue"/>
    </visual>
  </link>
  
<!-- Left Bogie Link -->
  <link name = "left_bogie_horizontal_strip">
    <visual>
      <origin xyz = "0 -0.175 0.2233" rpy = "1.57 0 0"/>
      <geometry>
        <box size = "0.38 0.025  0.003"/>
      </geometry>
      <material name="grey"/>
    </visual>
  </link>

 <joint name = "left_Bogie_to_Base_chassis_joint" type = "revolute">
    <parent link = "base_link"/>
    <child link = "left_bogie_horizontal_strip"/>
    <origin xyz = "0.245 -0.175 0.2233" rpy = "0 0 0"/>
    <axis xyz="0 1 0"/>
    <limit lower="-1.5708" upper="1.5708" effort="50" velocity="1.0"/>
  </joint>


  <link name = "left_bogie_rear_wheel_strip">
    <visual>
      <origin xyz = "0.228 -0.175 0.15" rpy = "1.57 -2.1293 0"/>
      <geometry>
        <box size = "0.183 0.025  0.003"/>
      </geometry>
      <material name="grey"/>
    </visual>
  </link>

  <joint name = "left_rear_wheel_strip_to_horizontal_strip" type = "fixed">
    <parent link = "left_bogie_horizontal_strip"/>
    <child link = "left_bogie_rear_wheel_strip"/>
    <origin xyz = "0.195 -0.175 0.2233" rpy = "0 0 0"/>
    <axis xyz="0 0 0"/>
  </joint>

  <link name = "left_bogie_to_rocker_strip">
  <visual>
      <origin xyz = " -0.1918 -0.175 0.21" rpy = "1.57 2.1293 0"/>
      <geometry>
        <box size = "0.043 0.025 0.003"/>
      </geometry>
      <material name="grey"/>
    </visual>
  </link>

  <joint name = "left_bogie_to_rocker_joint" type = "fixed">
    <parent link = "left_bogie_horizontal_strip"/>
    <child link = "left_bogie_to_rocker_strip"/>
    <origin xyz = " -0.195 -0.175 0.15" rpy = "0 0 0"/>
    <axis xyz = "0 0 0"/>
  </joint>

  <link name = "left_rocker_frontwheel_strip">
  <visual>
      <origin xyz = " -0.25 -0.175 0.138" rpy = "1.57 2.26 0"/>
      <geometry>
        <box size = "0.161 0.025 0.003"/>
      </geometry>
      <material name="grey"/>
    </visual>
  </link>

  <link name = "left_rocker_midwheel_strip">
  <visual>
      <origin xyz = " -0.16 -0.175 0.138" rpy = "1.57 0.8 0"/>
      <geometry>
        <box size = "0.147 0.025 0.003"/>
      </geometry>
      <material name="grey"/>
    </visual>
  </link>

  <joint name = "left_rocker_joint" type = "fixed">
    <parent link = "left_rocker_frontwheel_strip"/>
    <child link = "left_rocker_midwheel_strip"/>
    <origin xyz = " -0.195 -0.175 0.138" rpy = "0 0 0"/>
    <axis xyz = "0 0 0"/>
  </joint>

  <joint name = "left_rocker_joint_to_bogie" type = "revolute">
    <parent link = "left_bogie_horizontal_strip"/>
    <child link = "left_rocker_frontwheel_strip"/>
    <origin xyz = " -0.195 -0.175 0.138" rpy = "0 0 0"/>
    <axis xyz = "0 0 0"/>
    <limit lower="-1.5708" upper="1.5708" effort="50" velocity="1.0"/>
  </joint>

  <link name="left_front_wheel">
    <visual>
      <origin xyz="-0.3 -0.175 0.075" rpy="1.5708 0 0"/>
      <geometry>
        <cylinder length="0.04" radius="0.075"/>
      </geometry>
      <material name="red"/>
    </visual>
  </link>

  <joint name = "left_front_wheel_joint" type = "continuous">
    <parent link = "left_rocker_frontwheel_strip"/>
    <child link = "left_front_wheel"/>
    <origin xyz = " -0.3 -0.175 0.075" rpy = "0 0 0"/>
    <axis xyz = "0 1 0"/>
  </joint>

  <link name="left_mid_wheel">
    <visual>
      <origin xyz="-0.1 -0.175 0.075" rpy="1.5708 0 0"/>
      <geometry>
        <cylinder length="0.04" radius="0.075"/>
      </geometry>
      <material name="red"/>
    </visual>
  </link>

  <joint name = "left_front_mid_joint" type = "continuous">
    <parent link = "left_rocker_midwheel_strip"/>
    <child link = "left_mid_wheel"/>
    <origin xyz = " -0.1 -0.175 0.075" rpy = "0 0 0"/>
    <axis xyz = "0 1 0"/>
  </joint>
 
  <link name="left_rear_wheel">
    <visual>
      <origin xyz="0.25 -0.175 0.075" rpy="1.5708 0 0"/>
      <geometry>
        <cylinder length="0.04" radius="0.075"/>
      </geometry>
      <material name="red"/>
    </visual>
  </link>

  <joint name = "left_front_rear_joint" type = "continuous">
    <parent link = "left_bogie_rear_wheel_strip"/>
    <child link = "left_rear_wheel"/>
    <origin xyz = " 0.25 -0.175 0.075" rpy = "0 0 0"/>
    <axis xyz = "0 1 0"/>
  </joint>
 
<!-- Right Bogie Link -->
  <link name = "right_bogie_horizontal_strip">
    <visual>
      <origin xyz = "0 0.175 0.2233" rpy = "1.57 0 0"/>
      <geometry>
        <box size = "0.38 0.025  0.003"/>
      </geometry>
      <material name="grey"/>
    </visual>
  </link>

 <joint name = "right_Bogie_to_Base_chassis_joint" type = "revolute">
    <parent link = "base_link"/>
    <child link = "right_bogie_horizontal_strip"/>
    <origin xyz = "0.245 0.175 0.2233" rpy = "0 0 0"/>
    <axis xyz="0 1 0"/>
    <limit lower="-1.5708" upper="1.5708" effort="50" velocity="1.0"/>
  </joint>


  <link name = "right_bogie_rear_wheel_strip">
    <visual>
      <origin xyz = "0.228 0.175 0.15" rpy = "1.57 -2.1293 0"/>
      <geometry>
        <box size = "0.183 0.025  0.003"/>
      </geometry>
      <material name="grey"/>
    </visual>
  </link>

  <joint name = "rear_wheel_strip_to_horizontal_strip" type = "fixed">
    <parent link = "right_bogie_horizontal_strip"/>
    <child link = "right_bogie_rear_wheel_strip"/>
    <origin xyz = "0.195 0.175 0.2233" rpy = "0 0 0"/>
    <axis xyz="0 0 0"/>
  </joint>

  <link name = "right_bogie_to_rocker_strip">
  <visual>
      <origin xyz = " -0.1918 0.175 0.21" rpy = "1.57 2.1293 0"/>
      <geometry>
        <box size = "0.043 0.025 0.003"/>
      </geometry>
      <material name="grey"/>
    </visual>
  </link>

  <joint name = "right_bogie_to_rocker_joint" type = "fixed">
    <parent link = "right_bogie_horizontal_strip"/>
    <child link = "right_bogie_to_rocker_strip"/>
    <origin xyz = " -0.195 0.175 0.15" rpy = "0 0 0"/>
    <axis xyz = "0 0 0"/>
  </joint>

  <link name = "right_rocker_frontwheel_strip">
  <visual>
      <origin xyz = " -0.25 0.175 0.138" rpy = "1.57 2.26 0"/>
      <geometry>
        <box size = "0.161 0.025 0.003"/>
      </geometry>
      <material name="grey"/>
    </visual>
  </link>

  <link name = "right_rocker_midwheel_strip">
  <visual>
      <origin xyz = " -0.16 0.175 0.138" rpy = "1.57 0.8 0"/>
      <geometry>
        <box size = "0.147 0.025 0.003"/>
      </geometry>
      <material name="grey"/>
    </visual>
  </link>

  <joint name = "right_rocker_joint" type = "fixed">
    <parent link = "right_rocker_frontwheel_strip"/>
    <child link = "right_rocker_midwheel_strip"/>
    <origin xyz = " -0.195 0.175 0.138" rpy = "0 0 0"/>
    <axis xyz = "0 0 0"/>
  </joint>

  <joint name = "right_rocker_joint_to_bogie" type = "revolute">
    <parent link = "right_bogie_horizontal_strip"/>
    <child link = "right_rocker_frontwheel_strip"/>
    <origin xyz = " -0.195 0.175 0.138" rpy = "0 0 0"/>
    <axis xyz = "0 0 0"/>
    <limit lower="-1.5708" upper="1.5708" effort="50" velocity="1.0"/>
  </joint>

  <link name="right_front_wheel">
    <visual>
      <origin xyz="-0.3 0.175 0.075" rpy="1.5708 0 0"/>
      <geometry>
        <cylinder length="0.04" radius="0.075"/>
      </geometry>
      <material name="red"/>
    </visual>
  </link>

  <joint name = "right_front_wheel_joint" type = "continuous">
    <parent link = "right_rocker_frontwheel_strip"/>
    <child link = "right_front_wheel"/>
    <origin xyz = " -0.3 0.175 0.075" rpy = "0 0 0"/>
    <axis xyz = "0 1 0"/>
  </joint>

  <link name="right_mid_wheel">
    <visual>
      <origin xyz="-0.1 0.175 0.075" rpy="1.5708 0 0"/>
      <geometry>
        <cylinder length="0.04" radius="0.075"/>
      </geometry>
      <material name="red"/>
    </visual>
  </link>

  <joint name = "right_front_mid_joint" type = "continuous">
    <parent link = "right_rocker_midwheel_strip"/>
    <child link = "right_mid_wheel"/>
    <origin xyz = " -0.1 0.175 0.075" rpy = "0 0 0"/>
    <axis xyz = "0 1 0"/>
  </joint>
 
  <link name="right_rear_wheel">
    <visual>
      <origin xyz="0.25 0.175 0.075" rpy="1.5708 0 0"/>
      <geometry>
        <cylinder length="0.04" radius="0.075"/>
      </geometry>
      <material name="red"/>
    </visual>
  </link>

  <joint name = "right_front_rear_joint" type = "continuous">
    <parent link = "right_bogie_rear_wheel_strip"/>
    <child link = "right_rear_wheel"/>
    <origin xyz = " 0.25 0.175 0.075" rpy = "0 0 0"/>
    <axis xyz = "0 1 0"/>
  </joint>
</robot>
