<?xml version="1.0"?>
<robot name="rocker_bogie_bot_fixed">
  <gazebo reference="base_link">
    <pose>0 0 0.5 0 0 0</pose>
  </gazebo>
  <link name="base_link">
    <visual>
      <origin xyz="0 0 0.18" rpy="0 0 0"/>
      <geometry>
        <box size="0.49 0.35 0.1874"/>
      </geometry>
      <material name="steel">
        <color rgba="0.4 0.4 0.45 1"/>
      </material>
    </visual>
    <collision>
      <origin xyz="0 0 0.18"/>
      <geometry>
        <box size="0.49 0.35 0.1874"/>
      </geometry>
    </collision>
    <inertial>
      <origin xyz="0 0 0.18"/>
      <mass value="6.0"/>
      <inertia ixx="0.25" ixy="0.0" ixz="0.0" iyy="0.35" iyz="0.0" izz="0.45"/>
    </inertial>
  </link>
  <link name="left_rocker">
    <visual>
      <origin xyz="0.08 0.175 0.02" rpy="0 0 0"/>
      <geometry>
        <box size="0.2 0.06 0.04"/>
      </geometry>
    </visual>
    <collision>
      <origin xyz="0.08 0.175 0.02"/>
      <geometry>
        <box size="0.2 0.06 0.04"/>
      </geometry>
    </collision>
    <inertial>
      <origin xyz="0.08 0.175 0.02"/>
      <mass value="0.8"/>
      <inertia ixx="0.002" ixy="0" ixz="0" iyy="0.002" iyz="0" izz="0.003"/>
    </inertial>
  </link>
  <joint name="left_rocker_joint" type="revolute">
    <parent link="base_link"/>
    <child link="left_rocker"/>
    <origin xyz="0 0.175 0" rpy="0 0 0"/>
    <axis xyz="0 1 0"/>
    <limit lower="-1.5708" upper="1.5708" effort="50" velocity="1.0"/>
  </joint>
  <link name="left_front_wheel">
    <visual>
      <origin xyz="0.16117 0.175 -0.075" rpy="1.5708 0 0"/>
      <geometry>
        <cylinder length="0.04" radius="0.075"/>
      </geometry>
    </visual>
    <collision>
      <origin xyz="0.16117 0.175 -0.075" rpy="1.5708 0 0"/>
      <geometry>
        <cylinder length="0.04" radius="0.075"/>
      </geometry>
    </collision>
    <inertial>
      <origin xyz="0.16117 0.175 -0.075"/>
      <mass value="0.3"/>
      <inertia ixx="0.0006" ixy="0" ixz="0" iyy="0.0012" iyz="0" izz="0.0006"/>
    </inertial>
  </link>
  <joint name="left_front_wheel_joint" type="continuous">
    <parent link="left_rocker"/>
    <child link="left_front_wheel"/>
    <origin xyz="0.16117 0 -0.075" rpy="0 0 0"/>
    <axis xyz="0 1 0"/>
  </joint>
  <link name="left_bogie">
    <visual>
      <origin xyz="-0.12 0.175 -0.02" rpy="0 0 0"/>
      <geometry>
        <box size="0.25 0.06 0.04"/>
      </geometry>
    </visual>
    <collision>
      <origin xyz="-0.12 0.175 -0.02"/>
      <geometry>
        <box size="0.25 0.06 0.04"/>
      </geometry>
    </collision>
    <inertial>
      <origin xyz="-0.12 0.175 -0.02"/>
      <mass value="0.6"/>
      <inertia ixx="0.0015" ixy="0" ixz="0" iyy="0.0015" iyz="0" izz="0.002"/>
    </inertial>
  </link>
  <joint name="left_bogie_joint" type="revolute">
    <parent link="left_rocker"/>
    <child link="left_bogie"/>
    <origin xyz="-0.19452 0 0" rpy="0 0 0"/>
    <axis xyz="0 1 0"/>
    <limit lower="-1.5708" upper="1.5708" effort="50" velocity="1.0"/>
  </joint>
  <link name="left_middle_wheel">
    <visual>
      <origin xyz="-0.01133 0.175 -0.075" rpy="1.5708 0 0"/>
      <geometry>
        <cylinder length="0.04" radius="0.075"/>
      </geometry>
    </visual>
    <collision>
      <origin xyz="-0.01133 0.175 -0.075" rpy="1.5708 0 0"/>
      <geometry>
        <cylinder length="0.04" radius="0.075"/>
      </geometry>
    </collision>
    <inertial>
      <origin xyz="-0.01133 0.175 -0.075"/>
      <mass value="0.3"/>
      <inertia ixx="0.0006" ixy="0" ixz="0" iyy="0.0012" iyz="0" izz="0.0006"/>
    </inertial>
  </link>
  <joint name="left_middle_wheel_joint" type="continuous">
    <parent link="left_bogie"/>
    <child link="left_middle_wheel"/>
    <origin xyz="-0.01133 0 -0.075" rpy="0 0 0"/>
    <axis xyz="0 1 0"/>
  </joint>
  <link name="left_rear_wheel">
    <visual>
      <origin xyz="-0.37762 0.175 -0.075" rpy="1.5708 0 0"/>
      <geometry>
        <cylinder length="0.04" radius="0.075"/>
      </geometry>
    </visual>
    <collision>
      <origin xyz="-0.37762 0.175 -0.075" rpy="1.5708 0 0"/>
      <geometry>
        <cylinder length="0.04" radius="0.075"/>
      </geometry>
    </collision>
    <inertial>
      <origin xyz="-0.37762 0.175 -0.075"/>
      <mass value="0.3"/>
      <inertia ixx="0.0006" ixy="0" ixz="0" iyy="0.0012" iyz="0" izz="0.0006"/>
    </inertial>
  </link>
  <joint name="left_rear_wheel_joint" type="continuous">
    <parent link="left_bogie"/>
    <child link="left_rear_wheel"/>
    <origin xyz="-0.37762 0 -0.075" rpy="0 0 0"/>
    <axis xyz="0 1 0"/>
  </joint>
  <link name="right_rocker">
    <visual>
      <origin xyz="0.08 -0.175 0.02" rpy="0 0 0"/>
      <geometry>
        <box size="0.2 0.06 0.04"/>
      </geometry>
    </visual>
    <collision>
      <origin xyz="0.08 -0.175 0.02"/>
      <geometry>
        <box size="0.2 0.06 0.04"/>
      </geometry>
    </collision>
    <inertial>
      <origin xyz="0.08 -0.175 0.02"/>
      <mass value="0.8"/>
      <inertia ixx="0.002" ixy="0" ixz="0" iyy="0.002" iyz="0" izz="0.003"/>
    </inertial>
  </link>
  <joint name="right_rocker_joint" type="revolute">
    <parent link="base_link"/>
    <child link="right_rocker"/>
    <origin xyz="0 -0.175 0" rpy="0 0 0"/>
    <axis xyz="0 1 0"/>
    <limit lower="-1.5708" upper="1.5708" effort="50" velocity="1.0"/>
  </joint>
  <link name="right_front_wheel">
    <visual>
      <origin xyz="0.16117 -0.175 -0.075" rpy="1.5708 0 0"/>
      <geometry>
        <cylinder length="0.04" radius="0.075"/>
      </geometry>
    </visual>
    <collision>
      <origin xyz="0.16117 -0.175 -0.075" rpy="1.5708 0 0"/>
      <geometry>
        <cylinder length="0.04" radius="0.075"/>
      </geometry>
    </collision>
    <inertial>
      <origin xyz="0.16117 -0.175 -0.075"/>
      <mass value="0.3"/>
      <inertia ixx="0.0006" ixy="0" ixz="0" iyy="0.0012" iyz="0" izz="0.0006"/>
    </inertial>
  </link>
  <joint name="right_front_wheel_joint" type="continuous">
    <parent link="right_rocker"/>
    <child link="right_front_wheel"/>
    <origin xyz="0.16117 0 -0.075" rpy="0 0 0"/>
    <axis xyz="0 1 0"/>
  </joint>
  <link name="right_bogie">
    <visual>
      <origin xyz="-0.12 -0.175 -0.02" rpy="0 0 0"/>
      <geometry>
        <box size="0.25 0.06 0.04"/>
      </geometry>
    </visual>
    <collision>
      <origin xyz="-0.12 -0.175 -0.02"/>
      <geometry>
        <box size="0.25 0.06 0.04"/>
      </geometry>
    </collision>
    <inertial>
      <origin xyz="-0.12 -0.175 -0.02"/>
      <mass value="0.6"/>
      <inertia ixx="0.0015" ixy="0" ixz="0" iyy="0.0015" iyz="0" izz="0.002"/>
    </inertial>
  </link>
  <joint name="right_bogie_joint" type="revolute">
    <parent link="right_rocker"/>
    <child link="right_bogie"/>
    <origin xyz="-0.19452 0 0" rpy="0 0 0"/>
    <axis xyz="0 1 0"/>
    <limit lower="-1.5708" upper="1.5708" effort="50" velocity="1.0"/>
  </joint>
  <link name="right_middle_wheel">
    <visual>
      <origin xyz="-0.01133 -0.175 -0.075" rpy="1.5708 0 0"/>
      <geometry>
        <cylinder length="0.04" radius="0.075"/>
      </geometry>
    </visual>
    <collision>
      <origin xyz="-0.01133 -0.175 -0.075" rpy="1.5708 0 0"/>
      <geometry>
        <cylinder length="0.04" radius="0.075"/>
      </geometry>
    </collision>
    <inertial>
      <origin xyz="-0.01133 -0.175 -0.075"/>
      <mass value="0.3"/>
      <inertia ixx="0.0006" ixy="0" ixz="0" iyy="0.0012" iyz="0" izz="0.0006"/>
    </inertial>
  </link>
  <joint name="right_middle_wheel_joint" type="continuous">
    <parent link="right_bogie"/>
    <child link="right_middle_wheel"/>
    <origin xyz="-0.01133 0 -0.075" rpy="0 0 0"/>
    <axis xyz="0 1 0"/>
  </joint>
  <link name="right_rear_wheel">
    <visual>
      <origin xyz="-0.37762 -0.175 -0.075" rpy="1.5708 0 0"/>
      <geometry>
        <cylinder length="0.04" radius="0.075"/>
      </geometry>
    </visual>
    <collision>
      <origin xyz="-0.37762 -0.175 -0.075" rpy="1.5708 0 0"/>
      <geometry>
        <cylinder length="0.04" radius="0.075"/>
      </geometry>
    </collision>
    <inertial>
      <origin xyz="-0.37762 -0.175 -0.075"/>
      <mass value="0.3"/>
      <inertia ixx="0.0006" ixy="0" ixz="0" iyy="0.0012" iyz="0" izz="0.0006"/>
    </inertial>
  </link>
  <joint name="right_rear_wheel_joint" type="continuous">
    <parent link="right_bogie"/>
    <child link="right_rear_wheel"/>
    <origin xyz="-0.37762 0 -0.075" rpy="0 0 0"/>
    <axis xyz="0 1 0"/>
  </joint>
  <link name="imu_link">
    <visual>
      <origin xyz="0 0 0.08"/>
      <geometry>
        <sphere radius="0.02"/>
      </geometry>
    </visual>
    <inertial>
      <origin xyz="0 0 0.08"/>
      <mass value="0.01"/>
      <inertia ixx="0.00001" ixy="0" ixz="0" iyy="0.00001" iyz="0" izz="0.00001"/>
    </inertial>
  </link>
  <joint name="imu_joint" type="fixed">
    <parent link="base_link"/>
    <child link="imu_link"/>
    <origin xyz="0 0 0.08"/>
  </joint>
</robot>